<?xml version="1.0" encoding="utf-8"?>
<!-- This URDF was automatically created by SolidWorks to URDF Exporter! Originally created by Stephen Brawner (brawner@gmail.com) 
     Commit Version: 1.6.0-4-g7f85cfe  Build Version: 1.6.7995.38578
     For more information, please see http://wiki.ros.org/sw_urdf_exporter -->
<robot
  name="Assemblyfix2">
  <link
    name="base_link">
    <inertial>
      <origin
        xyz="4.2417E-05 0.014216 -0.0067866"
        rpy="0 0 0" />
      <mass
        value="6" />
      <inertia
        ixx="0.012704"
        ixy="2.2802E-18"
        ixz="5.5823E-06"
        iyy="0.016608"
        iyz="-3.2535E-15"
        izz="0.0041213" />
    </inertial>
    <visual>
      <origin
        xyz="0 0 0"
        rpy="0 0 0" />
      <geometry>
        <mesh
          filename="package://Assemblyfix2/meshes/base_link.STL" />
      </geometry>
      <material
        name="">
        <color
          rgba="0.79216 0.81961 0.93333 1" />
      </material>
    </visual>
    <collision>
      <origin
        xyz="0 0 0"
        rpy="0 0 0" />
      <geometry>
        <mesh
          filename="package://Assemblyfix2/meshes/base_link.STL" />
      </geometry>
    </collision>
  </link>
  <link
    name="rodakananbawah_Link">
    <inertial>
      <origin
        xyz="-7.08E-08 -7.5112E-08 -0.023421"
        rpy="0 0 0" />
      <mass
        value="0.1728" />
      <inertia
        ixx="4.6952E-05"
        ixy="8.8421E-18"
        ixz="-6.2487E-18"
        iyy="4.6952E-05"
        iyz="-6.7545E-18"
        izz="6.4174E-05" />
    </inertial>
    <visual>
      <origin
        xyz="0 0 0"
        rpy="0 0 0" />
      <geometry>
        <mesh
          filename="package://Assemblyfix2/meshes/rodakananbawah_Link.STL" />
      </geometry>
      <material
        name="">
        <color
          rgba="0.79216 0.81961 0.93333 1" />
      </material>
    </visual>
    <collision>
      <origin
        xyz="0 0 0"
        rpy="0 0 0" />
      <geometry>
        <mesh
          filename="package://Assemblyfix2/meshes/rodakananbawah_Link.STL" />
      </geometry>
    </collision>
  </link>
  <joint
    name="joint_kanan_bawah"
    type="continuous">
    <origin
      xyz="0.18345 -0.19987 -0.0044227"
      rpy="1.5708 0 1.5708" />
    <parent
      link="base_link" />
    <child
      link="rodakananbawah_Link" />
    <axis
      xyz="0 0 -1" />
  </joint>
  <link
    name="rodakanan_atas_Link">
    <inertial>
      <origin
        xyz="-7.08E-08 7.5112E-08 -0.023829"
        rpy="0 0 0" />
      <mass
        value="0.1728" />
      <inertia
        ixx="4.6952E-05"
        ixy="-8.8405E-18"
        ixz="6.1965E-18"
        iyy="4.6952E-05"
        iyz="-6.7669E-18"
        izz="6.4174E-05" />
    </inertial>
    <visual>
      <origin
        xyz="0 0 0"
        rpy="0 0 0" />
      <geometry>
        <mesh
          filename="package://Assemblyfix2/meshes/rodakanan_atas_Link.STL" />
      </geometry>
      <material
        name="">
        <color
          rgba="0.79216 0.81961 0.93333 1" />
      </material>
    </visual>
    <collision>
      <origin
        xyz="0 0 0"
        rpy="0 0 0" />
      <geometry>
        <mesh
          filename="package://Assemblyfix2/meshes/rodakanan_atas_Link.STL" />
      </geometry>
    </collision>
  </link>
  <joint
    name="joint_kanan_atas"
    type="continuous">
    <origin
      xyz="0.4 0 0"
      rpy="0 0 0" />
    <parent
      link="rodakananbawah_Link" />
    <child
      link="rodakanan_atas_Link" />
    <axis
      xyz="0 0 -1" />
  </joint>
  <link
    name="roda_kiri_atas_Link">
    <inertial>
      <origin
        xyz="7.5112E-08 -7.08E-08 0.023829"
        rpy="0 0 0" />
      <mass
        value="0.1728" />
      <inertia
        ixx="4.6952E-05"
        ixy="-8.839E-18"
        ixz="6.7911E-18"
        iyy="4.6952E-05"
        iyz="-6.2199E-18"
        izz="6.4174E-05" />
    </inertial>
    <visual>
      <origin
        xyz="0 0 0"
        rpy="0 0 0" />
      <geometry>
        <mesh
          filename="package://Assemblyfix2/meshes/roda_kiri_atas_Link.STL" />
      </geometry>
      <material
        name="">
        <color
          rgba="0.79216 0.81961 0.93333 1" />
      </material>
    </visual>
    <collision>
      <origin
        xyz="0 0 0"
        rpy="0 0 0" />
      <geometry>
        <mesh
          filename="package://Assemblyfix2/meshes/roda_kiri_atas_Link.STL" />
      </geometry>
    </collision>
  </link>
  <joint
    name="joint_roda_kiriatas"
    type="continuous">
    <origin
      xyz="0 0 -0.3665"
      rpy="0 0 0" />
    <parent
      link="rodakanan_atas_Link" />
    <child
      link="roda_kiri_atas_Link" />
    <axis
      xyz="0 0 1" />
  </joint>
  <link
    name="rodakiri_bawah_Link">
    <inertial>
      <origin
        xyz="2.5511E-08 -1.0002E-07 0.023829"
        rpy="0 0 0" />
      <mass
        value="0.1728" />
      <inertia
        ixx="4.6952E-05"
        ixy="-2.0434E-17"
        ixz="2.3817E-18"
        iyy="4.6952E-05"
        iyz="-8.9014E-18"
        izz="6.4174E-05" />
    </inertial>
    <visual>
      <origin
        xyz="0 0 0"
        rpy="0 0 0" />
      <geometry>
        <mesh
          filename="package://Assemblyfix2/meshes/rodakiri_bawah_Link.STL" />
      </geometry>
      <material
        name="">
        <color
          rgba="0.79216 0.81961 0.93333 1" />
      </material>
    </visual>
    <collision>
      <origin
        xyz="0 0 0"
        rpy="0 0 0" />
      <geometry>
        <mesh
          filename="package://Assemblyfix2/meshes/rodakiri_bawah_Link.STL" />
      </geometry>
    </collision>
  </link>
  <joint
    name="joint_rodakiri_bawah"
    type="continuous">
    <origin
      xyz="-0.4 0 0"
      rpy="0 0 0" />
    <parent
      link="roda_kiri_atas_Link" />
    <child
      link="rodakiri_bawah_Link" />
    <axis
      xyz="0 0 1" />
  </joint>
</robot>